<?xml version="1.0"?>
<robot xmlns:xacro="http://www.ros.org/wiki/xacro" name="amr_robot">

    <xacro:property name="chassis_length" value="0.4"/>
    <xacro:property name="chassis_width" value="0.3"/>
    <xacro:property name="chassis_height" value="0.1"/>
    <xacro:property name="wheel_radius" value="0.05"/>
    <xacro:property name="wheel_thickness" value="0.04"/>

    <link name="base_link"></link>

    <link name="chassis">
        <visual>
            <geometry>
                <box size="${chassis_length} ${chassis_width} ${chassis_height}"/>
            </geometry>
            <material name="blue">
                <color rgba="0.0 0.0 0.8 1.0"/>
            </material>
        </visual>
    </link>

    <joint name="base_to_chassis" type="fixed">
        <parent link="base_link"/>
        <child link="chassis"/>
        <origin xyz="0 0 0.05" rpy="0 0 0"/>
    </joint>

    <xacro:macro name="wheel" params="prefix x_reflect y_reflect">
        
        <link name="${prefix}_wheel">
            <visual>
                <origin xyz="0 0 0" rpy="${pi/2} 0 0"/>
                <geometry>
                    <cylinder radius="${wheel_radius}" length="${wheel_thickness}"/>
                </geometry>
                <material name="black">
                    <color rgba="0.1 0.1 0.1 1.0"/>
                </material>
            </visual>
        </link>

        <joint name="${prefix}_wheel_joint" type="continuous">
            <parent link="chassis"/>
            <child link="${prefix}_wheel"/>
            <origin xyz="${x_reflect * (chassis_length/2 - 0.05)} ${y_reflect * (chassis_width/2 + wheel_thickness/2)} -0.02" rpy="0 0 0"/>
            <axis xyz="0 1 0"/> </joint>

    </xacro:macro>

    <xacro:wheel prefix="front_left" x_reflect="1" y_reflect="1" />
    <xacro:wheel prefix="front_right" x_reflect="1" y_reflect="-1" />
    <xacro:wheel prefix="rear_left" x_reflect="-1" y_reflect="1" />
    <xacro:wheel prefix="rear_right" x_reflect="-1" y_reflect="-1" />

</robot>
